<sdf version='1.11'>
  <model name='all_bot'>
    <link name='base_footprint'>
      <inertial>
        <pose>-0.011666666666666671 0 0.08752583333333333 0 0 0</pose>
        <mass>0.59999999999999998</mass>
        <inertia>
          <ixx>0.00095935413291666632</ixx>
          <ixy>0</ixy>
          <ixz>0.00035195416666666671</ixz>
          <iyy>0.0033636512162499989</iyy>
          <iyz>0</iyz>
          <izz>0.003325830436666666</izz>
        </inertia>
      </inertial>
      <collision name='base_footprint_fixed_joint_lump__base_link_collision'>
        <pose>0 0 0.077469999999999997 0 0 0</pose>
        <geometry>
          <box>
            <size>0.24129999999999999 0.1016 0.063500000000000001</size>
          </box>
        </geometry>
      </collision>
      <collision name='base_footprint_fixed_joint_lump__lidar_link_collision_1'>
        <pose>-0.070000000000000007 0 0.13780500000000001 0 0 0</pose>
        <geometry>
          <box>
            <size>0.070040000000000005 0.070040000000000005 0.057149999999999999</size>
          </box>
        </geometry>
      </collision>
      <visual name='base_footprint_fixed_joint_lump__base_link_visual'>
        <pose>0 0 0.077469999999999997 0 0 0</pose>
        <geometry>
          <box>
            <size>0.24129999999999999 0.1016 0.063500000000000001</size>
          </box>
        </geometry>
        <material>
          <diffuse>0 0 0 1</diffuse>
          <ambient>0 0 0 1</ambient>
        </material>
      </visual>
      <visual name='base_footprint_fixed_joint_lump__lidar_link_visual_1'>
        <pose>-0.070000000000000007 0 0.13780500000000001 0 0 0</pose>
        <geometry>
          <cylinder>
            <length>0.057149999999999999</length>
            <radius>0.035020000000000003</radius>
          </cylinder>
        </geometry>
        <material>
          <diffuse>0 1 0 1</diffuse>
          <ambient>0 1 0 1</ambient>
        </material>
      </visual>
    </link>
    <joint name='base_back_left_wheel_joint' type='revolute'>
      <pose relative_to='base_footprint'>-0.060335 0.063500000000000001 0.03175 0 0 0</pose>
      <parent>base_footprint</parent>
      <child>back_left_wheel</child>
      <axis>
        <xyz>0 1 0</xyz>
        <limit>
          <lower>-inf</lower>
          <upper>inf</upper>
        </limit>
        <dynamics>
          <spring_reference>0</spring_reference>
          <spring_stiffness>0</spring_stiffness>
        </dynamics>
      </axis>
    </joint>
    <link name='back_left_wheel'>
      <pose relative_to='base_back_left_wheel_joint'>0 0 0 0 0 0</pose>
      <inertial>
        <pose>0 0 0 1.5700000000000001 0 0</pose>
        <mass>0.10000000000000001</mass>
        <inertia>
          <ixx>3.0577895833333332e-05</ixx>
          <ixy>0</ixy>
          <ixz>0</ixz>
          <iyy>3.0577895833333332e-05</iyy>
          <iyz>0</iyz>
          <izz>5.0403125000000007e-05</izz>
        </inertia>
      </inertial>
      <collision name='back_left_wheel_collision'>
        <pose>0 0 0 1.5700000000000001 0 0</pose>
        <geometry>
          <cylinder>
            <length>0.025399999999999999</length>
            <radius>0.03175</radius>
          </cylinder>
        </geometry>
      </collision>
      <visual name='back_left_wheel_visual'>
        <pose>0 0 0 1.5700000000000001 0 0</pose>
        <geometry>
          <cylinder>
            <length>0.025399999999999999</length>
            <radius>0.03175</radius>
          </cylinder>
        </geometry>
        <material>
          <diffuse>1 1 0 1</diffuse>
          <ambient>1 1 0 1</ambient>
        </material>
      </visual>
    </link>
    <joint name='base_back_right_wheel_joint' type='revolute'>
      <pose relative_to='base_footprint'>-0.060335 -0.063500000000000001 0.03175 0 0 0</pose>
      <parent>base_footprint</parent>
      <child>back_right_wheel</child>
      <axis>
        <xyz>0 1 0</xyz>
        <limit>
          <lower>-inf</lower>
          <upper>inf</upper>
        </limit>
        <dynamics>
          <spring_reference>0</spring_reference>
          <spring_stiffness>0</spring_stiffness>
        </dynamics>
      </axis>
    </joint>
    <link name='back_right_wheel'>
      <pose relative_to='base_back_right_wheel_joint'>0 0 0 0 0 0</pose>
      <inertial>
        <pose>0 0 0 1.5700000000000001 0 0</pose>
        <mass>0.10000000000000001</mass>
        <inertia>
          <ixx>3.0577895833333332e-05</ixx>
          <ixy>0</ixy>
          <ixz>0</ixz>
          <iyy>3.0577895833333332e-05</iyy>
          <iyz>0</iyz>
          <izz>5.0403125000000007e-05</izz>
        </inertia>
      </inertial>
      <collision name='back_right_wheel_collision'>
        <pose>0 0 0 1.5700000000000001 0 0</pose>
        <geometry>
          <cylinder>
            <length>0.025399999999999999</length>
            <radius>0.03175</radius>
          </cylinder>
        </geometry>
      </collision>
      <visual name='back_right_wheel_visual'>
        <pose>0 0 0 1.5700000000000001 0 0</pose>
        <geometry>
          <cylinder>
            <length>0.025399999999999999</length>
            <radius>0.03175</radius>
          </cylinder>
        </geometry>
        <material>
          <diffuse>1 1 0 1</diffuse>
          <ambient>1 1 0 1</ambient>
        </material>
      </visual>
    </link>
    <joint name='base_front_left_wheel_joint' type='revolute'>
      <pose relative_to='base_footprint'>0.060335 0.063500000000000001 0.03175 0 0 0</pose>
      <parent>base_footprint</parent>
      <child>front_left_wheel</child>
      <axis>
        <xyz>0 1 0</xyz>
        <limit>
          <lower>-inf</lower>
          <upper>inf</upper>
        </limit>
        <dynamics>
          <spring_reference>0</spring_reference>
          <spring_stiffness>0</spring_stiffness>
        </dynamics>
      </axis>
    </joint>
    <link name='front_left_wheel'>
      <pose relative_to='base_front_left_wheel_joint'>0 0 0 0 0 0</pose>
      <inertial>
        <pose>0 0 0 1.5700000000000001 0 0</pose>
        <mass>0.10000000000000001</mass>
        <inertia>
          <ixx>3.0577895833333332e-05</ixx>
          <ixy>0</ixy>
          <ixz>0</ixz>
          <iyy>3.0577895833333332e-05</iyy>
          <iyz>0</iyz>
          <izz>5.0403125000000007e-05</izz>
        </inertia>
      </inertial>
      <collision name='front_left_wheel_collision'>
        <pose>0 0 0 1.5700000000000001 0 0</pose>
        <geometry>
          <cylinder>
            <length>0.025399999999999999</length>
            <radius>0.03175</radius>
          </cylinder>
        </geometry>
      </collision>
      <visual name='front_left_wheel_visual'>
        <pose>0 0 0 1.5700000000000001 0 0</pose>
        <geometry>
          <cylinder>
            <length>0.025399999999999999</length>
            <radius>0.03175</radius>
          </cylinder>
        </geometry>
        <material>
          <diffuse>1 1 0 1</diffuse>
          <ambient>1 1 0 1</ambient>
        </material>
      </visual>
    </link>
    <joint name='base_front_right_wheel_joint' type='revolute'>
      <pose relative_to='base_footprint'>0.060335 -0.063500000000000001 0.03175 0 0 0</pose>
      <parent>base_footprint</parent>
      <child>front_right_wheel</child>
      <axis>
        <xyz>0 1 0</xyz>
        <limit>
          <lower>-inf</lower>
          <upper>inf</upper>
        </limit>
        <dynamics>
          <spring_reference>0</spring_reference>
          <spring_stiffness>0</spring_stiffness>
        </dynamics>
      </axis>
    </joint>
    <link name='front_right_wheel'>
      <pose relative_to='base_front_right_wheel_joint'>0 0 0 0 0 0</pose>
      <inertial>
        <pose>0 0 0 1.5700000000000001 0 0</pose>
        <mass>0.10000000000000001</mass>
        <inertia>
          <ixx>3.0577895833333332e-05</ixx>
          <ixy>0</ixy>
          <ixz>0</ixz>
          <iyy>3.0577895833333332e-05</iyy>
          <iyz>0</iyz>
          <izz>5.0403125000000007e-05</izz>
        </inertia>
      </inertial>
      <collision name='front_right_wheel_collision'>
        <pose>0 0 0 1.5700000000000001 0 0</pose>
        <geometry>
          <cylinder>
            <length>0.025399999999999999</length>
            <radius>0.03175</radius>
          </cylinder>
        </geometry>
      </collision>
      <visual name='front_right_wheel_visual'>
        <pose>0 0 0 1.5700000000000001 0 0</pose>
        <geometry>
          <cylinder>
            <length>0.025399999999999999</length>
            <radius>0.03175</radius>
          </cylinder>
        </geometry>
        <material>
          <diffuse>1 1 0 1</diffuse>
          <ambient>1 1 0 1</ambient>
        </material>
      </visual>
    </link>
    <frame name='base_lidar_joint' attached_to='base_link'>
      <pose>-0.070000000000000007 0 0.060335 0 0 0</pose>
    </frame>
    <frame name='lidar_link' attached_to='base_lidar_joint'>
      <pose>0 0 0 0 0 0</pose>
    </frame>
    <frame name='base_joint' attached_to='base_footprint'>
      <pose>0 0 0.077469999999999997 0 0 0</pose>
    </frame>
    <frame name='base_link' attached_to='base_joint'>
      <pose>0 0 0 0 0 0</pose>
    </frame>
    <joint name='imu_joint' type='fixed'>
		<parent>base_link</parent>
		<child>imu_link</child>
		<pose relative_to="base_link">0.0 0.0 0.01 0 0 0</pose>
	</joint>

	<link name='imu_link'>
		<pose relative_to="imu_joint"/>
		<visual name="imu_link_visual">
			<geometry>
			<box><size>
				0.1 0.1 0.1
			</size></box>
			</geometry>
		</visual>

		<collision name="imu_link_collision">
			<geometry>
			<box><size>
				0.1 0.1 0.1
			</size></box>
			</geometry>
		</collision>

		<xacro:inertial_box mass ="0.1" x="0.1" y="0.1" z="0.1">
			<origin xyz="0 0 0" rpy="0 0 0" />
		</xacro:inertial_box>

		<sensor name="imu_sensor" type="imu">
			<always_on>true</always_on>
			<update_rate>100</update_rate>
			<visualize>true</visualize>
			<topic>demo/imu</topic>
			<gz_frame_id>imu_link</gz_frame_id>
			<imu>
			<angular_velocity>
				<x>
				<noise type="gaussian">
					<mean>0.0</mean>
					<stddev>2e-4</stddev>
					<bias_mean>0.0000075</bias_mean>
					<bias_stddev>0.0000008</bias_stddev>
				</noise>
				</x>
				<y>
				<noise type="gaussian">
					<mean>0.0</mean>
					<stddev>2e-4</stddev>
					<bias_mean>0.0000075</bias_mean>
					<bias_stddev>0.0000008</bias_stddev>
				</noise>
				</y>
				<z>
				<noise type="gaussian">
					<mean>0.0</mean>
					<stddev>2e-4</stddev>
					<bias_mean>0.0000075</bias_mean>
					<bias_stddev>0.0000008</bias_stddev>
				</noise>
				</z>
			</angular_velocity>
			<linear_acceleration>
				<x>
				<noise type="gaussian">
					<mean>0.0</mean>
					<stddev>1.7e-2</stddev>
					<bias_mean>0.1</bias_mean>
					<bias_stddev>0.001</bias_stddev>
				</noise>
				</x>
				<y>
				<noise type="gaussian">
					<mean>0.0</mean>
					<stddev>1.7e-2</stddev>
					<bias_mean>0.1</bias_mean>
					<bias_stddev>0.001</bias_stddev>
				</noise>
				</y>
				<z>
				<noise type="gaussian">
					<mean>0.0</mean>
					<stddev>1.7e-2</stddev>
					<bias_mean>0.1</bias_mean>
					<bias_stddev>0.001</bias_stddev>
				</noise>
				</z>
			</linear_acceleration>
			</imu>
		</sensor>
	</link>

	<plugin filename="gz-sim-diff-drive-system" name="gz::sim::systems::DiffDrive">
		<!-- wheels -->
		<left_joint>base_front_left_wheel_joint base_back_left_wheel_joint </left_joint>
		<right_joint>base_front_right_wheel_joint base_back_right_wheel_joint</right_joint>

		<!-- kinematics -->
		<wheel_separation>0.1016</wheel_separation>
		<wheel_radius>0.03175</wheel_radius>

		<!-- limits -->
		<max_linear_acceleration>0.1</max_linear_acceleration>

		<!-- input -->
		<topic>/demo/cmd_vel</topic>

		<!-- output -->
		<odom_topic>/demo/odom</odom_topic>
		<tf_topic>/tf</tf_topic>

		<frame_id>odom</frame_id>
		<child_frame_id>base_link</child_frame_id>
	</plugin>

	<plugin
		filename="gz-sim-joint-state-publisher-system"
		name="gz::sim::systems::JointStatePublisher">
		<topic>joint_states</topic>
	</plugin>
  </model>
</sdf>
